Workbook
Name CompanyName: Guide!$E$10
Name Currency: Guide!$E$20

Sheet Cover Page
F4: =CompanyName -> Cronyx Mining Ltd
G5: Financial Model from 2026 to 2029
G20: Modeler's Name: | J20: John Ezugworie
G21: Contact Information: | J21: john.ezugworie31@gmail.com
G22: Purpose: | J22: For Learning Only

Sheet Guide
B2: =CompanyName -> Cronyx Mining Ltd
B4: Model Guide
B7: Model Details
C8: This section highlights informations about the company being modelled
C9: Company Information
D10: Name of the Company | E10: Cronyx Mining Ltd
D11: Business Location | E11: Nigeria
D12: Industry | E12: Mining
D13: Purpose of the Model | E13: For Learning Only
C16: Model Information
D17: Model Owner | E17: =CompanyName -> Cronyx Mining Ltd
D18: Circularity in Model
D19: Iteration Toggle
D20: Currency | E20: =_xlfn.UNICHAR(8358) -> ₦
D22: Version | E22: Vs 1.0
D23: Last Updated:
D24: Current Modeller | E24: John Ezugworie
B27: Model Structure and Navigation
C28: This section highlights the model structure and navigation
C29: Major Timings
D30: Model Start Date | E30: 46023
D31: Model forecast period | E31: 4
D32: Month in each period | E32: 12
D33: Quarter in a year | E33: 4
D34: Weeks in a year | E34: 52
D35: Days in a year | E35: 365
D36: Number of working days in a week | E36: 7
D37: Number of working days in a year | E37: =E34*E36 -> 364
D38: Model Forecast Start Year | E38: =YEAR(E30) -> 2026
D39: Model forecast end year | E39: =E38+E31-1 -> 2029
C41: Sheet Sructure
D42: Cover page
D43: Guide
D44: Inputs
D45: Income Statement
D46: Statement of Financial Position
D47: Cash Flow Statement
B50: Glossary
C51: This section highlights the key terms applied in the model
C52: Key terms
...

Sheet Input
B2: =CompanyName -> Cronyx Mining Ltd
C3: Inputs
G5: Start Date | I5: =H6+1 -> 46023 | J5: =I6+1 -> 46388 | K5: =J6+1 -> 46753 | L5: =K6+1 -> 47119
G6: End Date | H6: =Guide!E30-1 -> 46022 | I6: =EDATE(H6,12) -> 46387 | J6: =EDATE(I6,12) -> 46752 | K6: =EDATE(J6,12) -> 47118 | L6: =EDATE(K6,12) -> 47483
I7: =YEAR(I6) -> 2026 | J7: =YEAR(J6) -> 2027 | K7: =YEAR(K6) -> 2028 | L7: =YEAR(L6) -> 2029
D8: Descriptions | E8: Units | F8: Input | H8: Historical | I8: Forecast | J8: Forecast | K8: Forecast | L8: Forecast
B11: General & Macro-economic
C12: Assumptions
D13: Timing
D14: Counter | I14: 1 | J14: 2 | K14: 3 | L14: 4
D16: Inflation
D17: Revenue | E17: % | I17: 0 | J17: 0.25 | K17: 0.25 | L17: 0.25
D18: Direct Cost | E18: % of Revenue | I18: 0.20960987 | J18: 0.45 | K18: 0.45 | L18: 0.45
D19: Office and Admin expeses | E19: % of Gross Profit | I19: 0.2 | J19: 0.2 | K19: 0.2 | L19: 0.2
B21: Notes to the accounts
A23: 1 | C23: Revenue Assumptions
D25: Kaolin Sales per year
D26: Price per ton | E26: =_xlfn.UNICHAR(8358) -> ₦ | I26: 3000 | J26: =I26*(1+J17) -> 3750 | K26: =J26*(1+K17) -> 4687.5 | L26: =K26*(1+L17) -> 5859.375
D27: Tons per year | E27: 105 trucks per week x 45 tons | I27: =105*45*4*12 -> 226800
D28: Total Sales | E28: =_xlfn.UNICHAR(8358) -> ₦ | I28: =I26*$I$27 -> 680400000 | J28: =J26*$I$27 -> 850500000 | K28: =K26*$I$27 -> 1063125000 | L28: =L26*$I$27 -> 1328906250
D30: Revenue from Logistics
D31: Tons | E31: 80 trucks per week | I31: =80*45*4*12 -> 172800
D32: Price per ton | E32: =Currency -> ₦ | I32: 11000 | J32: =I32*(1+J17) -> 13750 | K32: =J32*(1+K17) -> 17187.5 | L32: =K32*(1+L17) -> 21484.375
D33: Total Sales | E33: =Currency -> ₦ | I33: =$I$31*I32 -> 1900800000 | J33: =$I$31*J32 -> 2376000000 | K33: =$I$31*K32 -> 2970000000 | L33: =$I$31*L32 -> 3712500000
D35: Total Revenue | E35: =Currency -> ₦ | H35: 243600643 | I35: =SUM(I33,I28) -> 2581200000 | J35: =SUM(J33,J28) -> 3226500000 | K35: =SUM(K33,K28) -> 4033125000 | L35: =SUM(L33,L28) -> 5041406250
A37: 2 | C37: Cost of Sales Assuptions
D39: Direct Cost of Kaolin
D40: Escavator diesel cost
D41: Diesel (on-site) per litre | E41: =Currency -> ₦ | I41: 1000
D42: No of litres (20 hrs per day) | I42: 400
I43: =I41*I42 -> 400000
D44: No of days | I44: 365
D45: Total cost | E45: =Currency -> ₦ | I45: =I43*I44 -> 146000000
D47: Logistics(on-site)
D48: Logistics(on-site) cost per day | I48: 14000
D49: No. of days | I49: 365
D50: Total cost | I50: =I48*I49 -> 5110000
D52: Operator wages
D53: Operator wages per day(3 operator) | I53: 30000
D54: No. of days | I54: 365
...

Sheet IS
B2: =CompanyName -> Cronyx Mining Ltd
C3: Income Statement
G5: Start Date | I5: =H6+1 -> 46023 | J5: =I6+1 -> 46388 | K5: =J6+1 -> 46753 | L5: =K6+1 -> 47119
G6: End Date | H6: =Guide!E30-1 -> 46022 | I6: =EDATE(H6,12) -> 46387 | J6: =EDATE(I6,12) -> 46752 | K6: =EDATE(J6,12) -> 47118 | L6: =EDATE(K6,12) -> 47483
I7: =YEAR(I6) -> 2026 | J7: =YEAR(J6) -> 2027 | K7: =YEAR(K6) -> 2028 | L7: =YEAR(L6) -> 2029
D8: Descriptions | E8: Note | H8: Historical | I8: Forecast | J8: Forecast | K8: Forecast | L8: Forecast
D9: Revenue | E9: 1 | H9: =Input!H35 -> 243600643 | I9: =Input!I35 -> 2581200000 | J9: =Input!J35 -> 3226500000 | K9: =Input!K35 -> 4033125000 | L9: =Input!L35 -> 5041406250
D10: Cost of Sales | E10: 2 | H10: =-Input!H71 -> -166139946 | I10: =-Input!I71 -> -541045000 | J10: =-Input!J71 -> -1451925000 | K10: =-Input!K71 -> -1814906250 | L10: =-Input!L71 -> -2.2686328e+09
D11: Gross Profit | H11: =SUM(H9:H10) -> 77460697 | I11: =SUM(I9:I10) -> 2040155000 | J11: =SUM(J9:J10) -> 1774575000 | K11: =SUM(K9:K10) -> 2218218750 | L11: =SUM(L9:L10) -> 2.7727734e+09
D12: Gross Profit Margin | H12: =H11/H9 -> 0.31798232 | I12: =I11/I9 -> 0.79039013 | J12: =J11/J9 -> 0.55 | K12: =K11/K9 -> 0.55 | L12: =L11/L9 -> 0.55
D14: Office and Admin expenses | E14: 3 | H14: =-Input!H73 -> -25131571 | I14: =-(I11*Input!I19) -> -408031000 | J14: =-(J11*Input!J19) -> -354915000 | K14: =-(K11*Input!K19) -> -443643750 | L14: =-(L11*Input!L19) -> -5.5455469e+08
D15: Payroll | E15: 4 | I15: =-Input!$I$81 -> -37200000 | J15: =-Input!$I$81 -> -37200000 | K15: =-Input!$I$81 -> -37200000 | L15: =-Input!$I$81 -> -37200000
D16: Insurance Payments | E16: 7 | I16: =-Input!$I$119 -> -53250000 | J16: =-Input!$I$119 -> -53250000 | K16: =-Input!$I$119 -> -53250000 | L16: =-Input!$I$119 -> -53250000
D17: EBITDA | H17: =H11+H14+H15+H16 -> 52329126 | I17: =I11+I14+I15+I16 -> 1541674000 | J17: =J11+J14+J15+J16 -> 1329210000 | K17: =K11+K14+K15+K16 -> 1684125000 | L17: =L11+L14+L15+L16 -> 2127768750
D18: Depreciation and Amortisation | E18: 6 | I18: =-Input!I112 -> -213000000 | J18: =-Input!J112 -> -213000000 | K18: =-Input!K112 -> -213000000 | L18: =-Input!L112 -> -213000000
D19: EBIT | H19: =SUM(H17:H18) -> 52329126 | I19: =SUM(I17:I18) -> 1328674000 | J19: =SUM(J17:J18) -> 1116210000 | K19: =SUM(K17:K18) -> 1471125000 | L19: =SUM(L17:L18) -> 1914768750
D20: Operating Profit Margin | H20: =H19/H9 -> 0.21481522 | I20: =I19/I9 -> 0.5147505 | J20: =J19/J9 -> 0.34595072 | K20: =K19/K9 -> 0.36476058 | L20: =L19/L9 -> 0.37980846
D22: Interest Expenses | E22: 11 | I22: =-Input!I153 -> -330000000 | J22: =-Input!J153 -> -2.788494e+08 | K22: =-Input!K153 -> -2.108191e+08 | L22: =-Input!L153 -> -1.203388e+08
D23: EBT/PBT | H23: =H19+H22 -> 52329126 | I23: =I19+I22 -> 998674000 | J23: =J19+J22 -> 8.373606e+08 | K23: =K19+K22 -> 1.2603059e+09 | L23: =L19+L22 -> 1.79443e+09
D24: Tax | E24: 8 | H24: =-Input!H122 -> -6800000 | I24: =-(IF(I23>0,Input!$E$124*I23,0)) -> -3.3954916e+08 | J24: =-(IF(J23>0,Input!$E$124*J23,0)) -> -2.847026e+08 | K24: =-(IF(K23>0,Input!$E$124*K23,0)) -> -4.2850401e+08 | L24: =-(IF(L23>0,Input!$E$124*L23,0)) -> -6.1010618e+08
D25: Net Profit/PAT | H25: =SUM(H23:H24) -> 45529126 | I25: =SUM(I23:I24) -> 659124840 | J25: =SUM(J23:J24) -> 5.52658e+08 | K25: =SUM(K23:K24) -> 8.318019e+08 | L25: =SUM(L23:L24) -> 1.1843238e+09
D26: Net Profit Margin | H26: =H25/H9 -> 0.18690068 | I26: =I25/I9 -> 0.25535597 | J26: =J25/J9 -> 0.17128715 | K26: =K25/K9 -> 0.20624253 | L26: =L25/L9 -> 0.23491933
D28: Retained Earnings
D29: Opening Balance | H29: =G32 -> 0 | I29: =H32 -> 45529126 | J29: =I32 -> 572828998 | K29: =J32 -> 1.0149554e+09 | L29: =K32 -> 1.6803969e+09
D30: PAT | H30: =H25 -> 45529126 | I30: =I25 -> 659124840 | J30: =J25 -> 5.52658e+08 | K30: =K25 -> 8.318019e+08 | L30: =L25 -> 1.1843238e+09
D31: Dividend | I31: =IF(I30>0,I30*0.2,0) -> 131824968 | J31: =IF(J30>0,J30*0.2,0) -> 1.105316e+08 | K31: =IF(K30>0,K30*0.2,0) -> 1.6636038e+08 | L31: =IF(L30>0,L30*0.2,0) -> 2.3686475e+08
D32: Closing Balance | H32: =H29+H30-H31 -> 45529126 | I32: =I29+I30-I31 -> 572828998 | J32: =J29+J30-J31 -> 1.0149554e+09 | K32: =K29+K30-K31 -> 1.6803969e+09 | L32: =L29+L30-L31 -> 2.6278559e+09

Sheet SOFP
B2: =CompanyName -> Cronyx Mining Ltd
C3: Statement of Financial Position
G5: Start Date | I5: =H6+1 -> 46023 | J5: =I6+1 -> 46388 | K5: =J6+1 -> 46753 | L5: =K6+1 -> 47119
G6: End Date | H6: =Guide!E30-1 -> 46022 | I6: =EDATE(H6,12) -> 46387 | J6: =EDATE(I6,12) -> 46752 | K6: =EDATE(J6,12) -> 47118 | L6: =EDATE(K6,12) -> 47483
I7: =YEAR(I6) -> 2026 | J7: =YEAR(J6) -> 2027 | K7: =YEAR(K6) -> 2028 | L7: =YEAR(L6) -> 2029
D8: Descriptions | E8: Notes | H8: Historical | I8: Forecast | J8: Forecast | K8: Forecast | L8: Forecast
D9: Non Current Assets
D10: Plant Properties and Equipment | E10: 5 | I10: =Input!I113 -> 852000000 | J10: =Input!J113 -> 639000000 | K10: =Input!K113 -> 426000000 | L10: =Input!L113 -> 213000000
D11: Total Non Current Assets | I11: =SUM(I10) -> 852000000 | J11: =SUM(J10) -> 639000000 | K11: =SUM(K10) -> 426000000 | L11: =SUM(L10) -> 213000000
D13: Current Assets
D14: Cash | H14: =CFS!H40 -> 45529126 | I14: =CFS!I40 -> 3.8902745e+08 | J14: =CFS!J40 -> 7.3505183e+08 | K14: =CFS!K40 -> 1.2531233e+09 | L14: =CFS!L40 -> 1.9411851e+09
D15: Inventory | E15: 9 | I15: =Input!I132 -> 59292603 | J15: =Input!J132 -> 1.5911507e+08 | K15: =Input!K132 -> 1.9889384e+08 | L15: =Input!L132 -> 2.4861729e+08
D16: Receivables | E16: 9 | I16: =Input!I133 -> 2.1215342e+08 | J16: =Input!J133 -> 2.6519178e+08 | K16: =Input!K133 -> 3.3148973e+08 | L16: =Input!L133 -> 4.1436216e+08
D17: Total Current Assets | I17: =SUM(I14:I16) -> 6.6047348e+08 | J17: =SUM(J14:J16) -> 1.1593587e+09 | K17: =SUM(K14:K16) -> 1.7835069e+09 | L17: =SUM(L14:L16) -> 2.6041646e+09
D19: Total Assets | H19: =H14 -> 45529126 | I19: =SUM(I11,I17) -> 1.5124735e+09 | J19: =SUM(J11,J17) -> 1.7983587e+09 | K19: =SUM(K11,K17) -> 2.2095069e+09 | L19: =SUM(L11,L17) -> 2.8171646e+09
D22: Non Current Liabilities
D23: Term Loan | E23: 11 | I23: =Input!I154 -> 8.4499818e+08 | J23: =Input!J154 -> 6.3884575e+08 | K23: =Input!K154 -> 3.6466303e+08 | L23: =Input!L154 -> 0
D24: Total Non Current Liabilities | I24: =SUM(I23) -> 8.4499818e+08 | J24: =SUM(J23) -> 6.3884575e+08 | K24: =SUM(K23) -> 3.6466303e+08 | L24: =SUM(L23) -> 0
D26: Current Liabilities
D27: Payables | E27: 9 | I27: =Input!I135 -> 29646301 | J27: =Input!J135 -> 79557534 | K27: =Input!K135 -> 99446918 | L27: =Input!L135 -> 1.2430865e+08
D28: Total Current Liabilities | I28: =SUM(I27) -> 29646301 | J28: =SUM(J27) -> 79557534 | K28: =SUM(K27) -> 99446918 | L28: =SUM(L27) -> 1.2430865e+08
D30: Total Liabilities | I30: =SUM(I24,I28) -> 8.7464448e+08 | J30: =SUM(J24,J28) -> 7.1840329e+08 | K30: =SUM(K24,K28) -> 4.6410994e+08 | L30: =SUM(L24,L28) -> 1.2430865e+08
D32: Equity
D33: Equity Injection/Share Capital | E33: 11 | I33: =Input!$E$139 -> 65000000 | J33: =Input!$E$139 -> 65000000 | K33: =Input!$E$139 -> 65000000 | L33: =Input!$E$139 -> 65000000
D34: Retained Earnings | H34: =IS!H32 -> 45529126 | I34: =IS!I32 -> 572828998 | J34: =IS!J32 -> 1.0149554e+09 | K34: =IS!K32 -> 1.6803969e+09 | L34: =IS!L32 -> 2.6278559e+09
D35: Total Equity | H35: =SUM(H33:H34) -> 45529126 | I35: =SUM(I33:I34) -> 637828998 | J35: =SUM(J33:J34) -> 1.0799554e+09 | K35: =SUM(K33:K34) -> 1.7453969e+09 | L35: =SUM(L33:L34) -> 2.6928559e+09
D37: Total Liabilities and Equity | H37: =SUM(H30,H35) -> 45529126 | I37: =SUM(I30,I35) -> 1.5124735e+09 | J37: =SUM(J30,J35) -> 1.7983587e+09 | K37: =SUM(K30,K35) -> 2.2095069e+09 | L37: =SUM(L30,L35) -> 2.8171646e+09
D39: Total Asset = Total Liabilities + Equity | I39: =I19=I37 -> TRUE | J39: =J19=J37 -> TRUE | K39: =K19=K37 -> TRUE | L39: =L19=L37 -> TRUE
D40: Check | I40: =I37-I19 -> 0 | J40: =J37-J19 -> 0 | K40: =K37-K19 -> 0 | L40: =L37-L19 -> 0

Sheet CFS
B2: =CompanyName -> Cronyx Mining Ltd
C3: Cashflow Statement
G5: Start Date | I5: =H6+1 -> 46023 | J5: =I6+1 -> 46388 | K5: =J6+1 -> 46753 | L5: =K6+1 -> 47119
G6: End Date | H6: =Guide!E30-1 -> 46022 | I6: =EDATE(H6,12) -> 46387 | J6: =EDATE(I6,12) -> 46752 | K6: =EDATE(J6,12) -> 47118 | L6: =EDATE(K6,12) -> 47483
I7: =YEAR(I6) -> 2026 | J7: =YEAR(J6) -> 2027 | K7: =YEAR(K6) -> 2028 | L7: =YEAR(L6) -> 2029
D8: Descriptions | E8: Notes | H8: Hisorical | I8: Forecast | J8: Forecast | K8: Forecast | L8: Forecast
D9: Cashflows from Operating Activities
D10: EBITDA | H10: =IS!H17 -> 52329126 | I10: =IS!I17 -> 1541674000 | J10: =IS!J17 -> 1329210000 | K10: =IS!K17 -> 1684125000 | L10: =IS!L17 -> 2127768750
D11: Adjust for Changes in Working Capital
D12: Inventory | I12: =SOFP!H15-SOFP!I15 -> -59292603 | J12: =SOFP!I15-SOFP!J15 -> -99822466 | K12: =SOFP!J15-SOFP!K15 -> -39778767 | L12: =SOFP!K15-SOFP!L15 -> -49723459
D13: Receivables | I13: =SOFP!H16-SOFP!I16 -> -2.1215342e+08 | J13: =SOFP!I16-SOFP!J16 -> -53038356 | K13: =SOFP!J16-SOFP!K16 -> -66297945 | L13: =SOFP!K16-SOFP!L16 -> -82872432
D14: Payables | I14: =SOFP!I27-SOFP!H27 -> 29646301 | J14: =SOFP!J27-SOFP!I27 -> 49911233 | K14: =SOFP!K27-SOFP!J27 -> 19889384 | L14: =SOFP!L27-SOFP!K27 -> 24861729
D15: Net changes in working capital | I15: =SUM(I12:I14) -> -2.4179973e+08 | J15: =SUM(J12:J14) -> -1.0294959e+08 | K15: =SUM(K12:K14) -> -86187329 | L15: =SUM(L12:L14) -> -1.0773416e+08
D17: Tax | H17: =IS!H24 -> -6800000 | I17: =IS!I24 -> -3.3954916e+08 | J17: =IS!J24 -> -2.847026e+08 | K17: =IS!K24 -> -4.2850401e+08 | L17: =IS!L24 -> -6.1010618e+08
D19: Total Cashflows from Operating Activities | H19: =H10+H15+H17 -> 45529126 | I19: =I10+I15+I17 -> 9.6032511e+08 | J19: =J10+J15+J17 -> 9.4155781e+08 | K19: =K10+K15+K17 -> 1.1694337e+09 | L19: =L10+L15+L17 -> 1.4099284e+09
D22: Cashflows from Investing Activities
D23: PPE | I23: =-Input!I111 -> -1065000000 | J23: =-Input!J111 -> 0 | K23: =-Input!K111 -> 0 | L23: =-Input!L111 -> 0
D25: Total Cashflows from Investing Activites | I25: =I23 -> -1065000000 | J25: =J23 -> 0 | K25: =K23 -> 0 | L25: =L23 -> 0
D28: Cashflows from Financing Activities
D29: Equity Injection | I29: =Input!E139 -> 65000000 | J29: =Input!F139 -> 0 | K29: =Input!G139 -> 0 | L29: =Input!H139 -> 0
D30: Term Loan | I30: =Input!E140 -> 1000000000 | J30: =Input!F140 -> 0 | K30: =Input!G140 -> 0 | L30: =Input!H140 -> 0
D31: Principal Repayment | I31: =-Input!I152 -> -1.5500182e+08 | J31: =-Input!J152 -> -2.0615243e+08 | K31: =-Input!K152 -> -2.7418273e+08 | L31: =-Input!L152 -> -3.6466303e+08
D32: Interest Repayment | I32: =-Input!I153 -> -330000000 | J32: =-Input!J153 -> -2.788494e+08 | K32: =-Input!K153 -> -2.108191e+08 | L32: =-Input!L153 -> -1.203388e+08
D33: Dividend | H33: =-IS!H31 -> 0 | I33: =-IS!I31 -> -131824968 | J33: =-IS!J31 -> -1.105316e+08 | K33: =-IS!K31 -> -1.6636038e+08 | L33: =-IS!L31 -> -2.3686475e+08
D35: Total Cashflows from Financing Activites | H35: =SUM(H29:H33) -> 0 | I35: =SUM(I29:I33) -> 4.4817321e+08 | J35: =SUM(J29:J33) -> -5.9553342e+08 | K35: =SUM(K29:K33) -> -6.513622e+08 | L35: =SUM(L29:L33) -> -7.2186658e+08
D38: Cash During the Year | H38: =H35+H25+H19 -> 45529126 | I38: =I35+I25+I19 -> 3.4349832e+08 | J38: =J35+J25+J19 -> 3.4602438e+08 | K38: =K35+K25+K19 -> 5.1807146e+08 | L38: =L35+L25+L19 -> 6.8806183e+08
D39: Cash at the Beginning | H39: =G40 -> 0 | I39: =H40 -> 45529126 | J39: =I40 -> 3.8902745e+08 | K39: =J40 -> 7.3505183e+08 | L39: =K40 -> 1.2531233e+09
D40: Cash at the End of the Year | H40: =SUM(H38:H39) -> 45529126 | I40: =SUM(I38:I39) -> 3.8902745e+08 | J40: =SUM(J38:J39) -> 7.3505183e+08 | K40: =SUM(K38:K39) -> 1.2531233e+09 | L40: =SUM(L38:L39) -> 1.9411851e+09
